#from django.core.urlresolvers import reverse
from django.urls import reverse
from django.urls import resolve
from django.test import TestCase
from .views import home, board_topics
from .models import Board
from .forms import NewTopicForm


class HomeTests(TestCase):
    def setUp(self):
        self.board = Board.objects.create(name='Django', description='Django board.')
        url = reverse('home')
        self.response = self.client.get(url)

    def test_home_view_status_code(self):
        self.assertEquals(self.response.status_code, 200)

    def test_home_url_resolves_home_view(self):
        view = resolve('/')
        self.assertEquals(view.func, home)

    def test_home_view_contains_link_to_topics_page(self):
        board_topics_url = reverse('board_topics', kwargs={'pk': self.board.pk})
        self.assertContains(self.response, 'href="{0}"'.format(board_topics_url))



class NewTopicTests(TestCase):
    # ... other tests

    def test_contains_form(self):  # <- new test
        url = reverse('new_topic', kwargs={'pk': 1})
        response = self.client.get(url)
        form = response.context.get('form')
        self.assertIsInstance(form, NewTopicForm)

    def test_new_topic_invalid_post_data(self):  # <- updated this one
        '''
        Invalid post data should not redirect
        The expected behavior is to show the form again with validation errors
        '''
        url = reverse('new_topic', kwargs={'pk': 1})
        response = self.client.post(url, {})
        form = response.context.get('form')
        self.assertEquals(response.status_code, 200)
        self.assertTrue(form.errors)

